Workbook

Sheet RESUMEN
A1: CARTERA ENERGÍA E INFRAESTRUCTURA DE IA
A2: Última actualización: 10/08/2026 16:59
A3: Datos: 2021-08-09 a 2026-08-07 · 1255 ruedas · 4.98 años · precios Stooq (ajustados por splits, no por dividendos)
A6: PARÁMETROS (editables — amarillo)
A7: Tasa libre de riesgo | B7: 0.0465
A8: Días hábiles | B8: 252
A9: Confianza VaR | B9: 0.99
A10: Capital USD | B10: 100000
A11: Peso mínimo | B11: 0.05
A12: Peso máximo | B12: 0.3
A13: Tope YPF | B13: 0.1
A14: rf diaria | B14: =(1+B7)^(1/B8)-1 -> 0.00018037842
A15: z (VaR) | B15: =_xlfn.NORM.S.INV(B9) -> 2.3263479
A17: ESTADÍSTICA POR ACTIVO
A18: Ticker | B18: Nombre | C18: Bloque | D18: Div yield | E18: Obs | F18: Ret medio diario | G18: Ret precio anual | H18: RET TOTAL aritm. | I18: CAGR precio | J18: CAGR TOTAL | K18: Volat. anual | L18: Sharpe (CAGR) | M18: Peor día | N18: Curtosis
A19: XOM | B19: Exxon Mobil | C19: O&G integrada | D19: 0.0269 | E19: =COUNT(RETORNOS!$B$5:$B$1300) -> 1254 | F19: =AVERAGE(RETORNOS!$B$5:$B$1300) -> 0.00098055627 | G19: =(1+F19)^$B$8-1 -> 0.28015237 | H19: =(1+G19)*(1+D19)-1 -> 0.31458847 | I19: {=IFERROR((INDEX(PRECIOS!$B$4:$B$1300,COUNT(PRECIOS!$B$4:$B$1300))/PRECIOS!$B$4)^($B$8/E19)-1,"")} -> 0.23527247 | J19: =IFERROR((1+I19)*(1+D19)-1,"") -> 0.2685013 | K19: =_xlfn.STDEV.S(RETORNOS!$B$5:$B$1300)*SQRT($B$8) -> 0.26710401 | L19: =(J19-$B$7)/K19 -> 0.83114179 | M19: =IFERROR(MIN(RETORNOS!$B$5:$B$1300),"") -> -0.078852428 | N19: =IFERROR(KURT(RETORNOS!$B$5:$B$1300),"") -> 1.3713498
A20: SO | B20: Southern Company | C20: Utility regulada | D20: 0.0322 | E20: =COUNT(RETORNOS!$C$5:$C$1300) -> 1254 | F20: =AVERAGE(RETORNOS!$C$5:$C$1300) -> 0.00040180927 | G20: =(1+F20)^$B$8-1 -> 0.10653731 | H20: =(1+G20)*(1+D20)-1 -> 0.14216781 | I20: {=IFERROR((INDEX(PRECIOS!$C$4:$C$1300,COUNT(PRECIOS!$C$4:$C$1300))/PRECIOS!$C$4)^($B$8/E20)-1,"")} -> 0.087312173 | J20: =IFERROR((1+I20)*(1+D20)-1,"") -> 0.12232363 | K20: =_xlfn.STDEV.S(RETORNOS!$C$5:$C$1300)*SQRT($B$8) -> 0.18732734 | L20: =(J20-$B$7)/K20 -> 0.40476541 | M20: =IFERROR(MIN(RETORNOS!$C$5:$C$1300),"") -> -0.046991788 | N20: =IFERROR(KURT(RETORNOS!$C$5:$C$1300),"") -> 1.1337427
A21: VST | B21: Vistra | C21: IPP merchant | D21: 0.0065 | E21: =COUNT(RETORNOS!$D$5:$D$1300) -> 1254 | F21: =AVERAGE(RETORNOS!$D$5:$D$1300) -> 0.0021078608 | G21: =(1+F21)^$B$8-1 -> 0.69998916 | H21: =(1+G21)*(1+D21)-1 -> 0.71103909 | I21: {=IFERROR((INDEX(PRECIOS!$D$4:$D$1300,COUNT(PRECIOS!$D$4:$D$1300))/PRECIOS!$D$4)^($B$8/E21)-1,"")} -> 0.51086594 | J21: =IFERROR((1+I21)*(1+D21)-1,"") -> 0.52068657 | K21: =_xlfn.STDEV.S(RETORNOS!$D$5:$D$1300)*SQRT($B$8) -> 0.48303337 | L21: =(J21-$B$7)/K21 -> 0.98168491 | M21: =IFERROR(MIN(RETORNOS!$D$5:$D$1300),"") -> -0.28271676 | N21: =IFERROR(KURT(RETORNOS!$D$5:$D$1300),"") -> 9.245752
A22: ETN | B22: Eaton Corp | C22: Equipamiento eléctrico | D22: 0.0109 | E22: =COUNT(RETORNOS!$E$5:$E$1300) -> 1254 | F22: =AVERAGE(RETORNOS!$E$5:$E$1300) -> 0.0010273429 | G22: =(1+F22)^$B$8-1 -> 0.29531968 | H22: =(1+G22)*(1+D22)-1 -> 0.30943866 | I22: {=IFERROR((INDEX(PRECIOS!$E$4:$E$1300,COUNT(PRECIOS!$E$4:$E$1300))/PRECIOS!$E$4)^($B$8/E22)-1,"")} -> 0.23280963 | J22: =IFERROR((1+I22)*(1+D22)-1,"") -> 0.24624726 | K22: =_xlfn.STDEV.S(RETORNOS!$E$5:$E$1300)*SQRT($B$8) -> 0.31386658 | L22: =(J22-$B$7)/K22 -> 0.63640817 | M22: =IFERROR(MIN(RETORNOS!$E$5:$E$1300),"") -> -0.15564529 | N22: =IFERROR(KURT(RETORNOS!$E$5:$E$1300),"") -> 5.6058745
A23: YPF | B23: YPF | C23: Upstream Argentina | D23: 0 | E23: =COUNT(RETORNOS!$F$5:$F$1300) -> 1254 | F23: =AVERAGE(RETORNOS!$F$5:$F$1300) -> 0.0024831323 | G23: =(1+F23)^$B$8-1 -> 0.86819684 | H23: =(1+G23)*(1+D23)-1 -> 0.86819684 | I23: {=IFERROR((INDEX(PRECIOS!$F$4:$F$1300,COUNT(PRECIOS!$F$4:$F$1300))/PRECIOS!$F$4)^($B$8/E23)-1,"")} -> 0.6183122 | J23: =IFERROR((1+I23)*(1+D23)-1,"") -> 0.6183122 | K23: =_xlfn.STDEV.S(RETORNOS!$F$5:$F$1300)*SQRT($B$8) -> 0.54507661 | L23: =(J23-$B$7)/K23 -> 1.0490492 | M23: =IFERROR(MIN(RETORNOS!$F$5:$F$1300),"") -> -0.15342199 | N23: =IFERROR(KURT(RETORNOS!$F$5:$F$1300),"") -> 16.002764
A24: WMB | B24: Williams Cos | C24: Midstream gas | D24: 0.0291 | E24: =COUNT(RETORNOS!$G$5:$G$1300) -> 1254 | F24: =AVERAGE(RETORNOS!$G$5:$G$1300) -> 0.0010126121 | G24: =(1+F24)^$B$8-1 -> 0.29052504 | H24: =(1+G24)*(1+D24)-1 -> 0.32807932 | I24: {=IFERROR((INDEX(PRECIOS!$G$4:$G$1300,COUNT(PRECIOS!$G$4:$G$1300))/PRECIOS!$G$4)^($B$8/E24)-1,"")} -> 0.25409461 | J24: =IFERROR((1+I24)*(1+D24)-1,"") -> 0.29058876 | K24: =_xlfn.STDEV.S(RETORNOS!$G$5:$G$1300)*SQRT($B$8) -> 0.23904848 | L24: =(J24-$B$7)/K24 -> 1.0210848 | M24: =IFERROR(MIN(RETORNOS!$G$5:$G$1300),"") -> -0.084270606 | N24: =IFERROR(KURT(RETORNOS!$G$5:$G$1300),"") -> 2.0992603
A25: XLE | B25: SPDR Energy | C25: Benchmark 1 | D25: 0.03 | E25: =COUNT(RETORNOS!$H$5:$H$1300) -> 1254 | F25: =AVERAGE(RETORNOS!$H$5:$H$1300) -> 0.00095008751 | G25: =(1+F25)^$B$8-1 -> 0.27037024 | H25: =(1+G25)*(1+D25)-1 -> 0.30848135 | I25: {=IFERROR((INDEX(PRECIOS!$H$4:$H$1300,COUNT(PRECIOS!$H$4:$H$1300))/PRECIOS!$H$4)^($B$8/E25)-1,"")} -> 0.22881704 | J25: =IFERROR((1+I25)*(1+D25)-1,"") -> 0.26568155 | K25: =_xlfn.STDEV.S(RETORNOS!$H$5:$H$1300)*SQRT($B$8) -> 0.25752175 | L25: =(J25-$B$7)/K25 -> 0.85111858 | M25: =IFERROR(MIN(RETORNOS!$H$5:$H$1300),"") -> -0.091998184 | N25: =IFERROR(KURT(RETORNOS!$H$5:$H$1300),"") -> 2.6809704
A26: XLU | B26: SPDR Utilities | C26: Benchmark 2 | D26: 0.028 | E26: =COUNT(RETORNOS!$I$5:$I$1300) -> 1254 | F26: =AVERAGE(RETORNOS!$I$5:$I$1300) -> 0.00037437658 | G26: =(1+F26)^$B$8-1 -> 0.098917103 | H26: =(1+G26)*(1+D26)-1 -> 0.12968678 | I26: {=IFERROR((INDEX(PRECIOS!$I$4:$I$1300,COUNT(PRECIOS!$I$4:$I$1300))/PRECIOS!$I$4)^($B$8/E26)-1,"")} -> 0.08251416 | J26: =IFERROR((1+I26)*(1+D26)-1,"") -> 0.11282456 | K26: =_xlfn.STDEV.S(RETORNOS!$I$5:$I$1300)*SQRT($B$8) -> 0.17338262 | L26: =(J26-$B$7)/K26 -> 0.38253291 | M26: =IFERROR(MIN(RETORNOS!$I$5:$I$1300),"") -> -0.055626589 | N26: =IFERROR(KURT(RETORNOS!$I$5:$I$1300),"") -> 1.69321
A27: Columna H = insumo del optimizador (aritmético). Columna J = rendimiento real (CAGR), el que va al reporte.
A29: CARTERA RECOMENDADA
A30: Activo | B30: Peso | C30: Bloque
A31: (XOM) | B31: =OPTIMIZACION!$B$5 -> 0.25 | C31: O&G integrada
A32: (SO) | B32: =OPTIMIZACION!$B$6 -> 0.25 | C32: Utility regulada
A33: (VST) | B33: =OPTIMIZACION!$B$7 -> 0.1 | C33: IPP merchant
A34: (ETN) | B34: =OPTIMIZACION!$B$8 -> 0.1 | C34: Equipamiento eléctrico
A35: (YPF) | B35: =OPTIMIZACION!$B$9 -> 0.1 | C35: Upstream Argentina
A36: (WMB) | B36: =OPTIMIZACION!$B$10 -> 0.2 | C36: Midstream gas
A37: SUMA | B37: =SUM(B31:B36) -> 1
A39: MÉTRICAS DE LA CARTERA
A40: Métrica | B40: Valor | C40: Lectura
A41: Retorno esperado (aritmético) | B41: =OPTIMIZACION!B17 -> 0.35207555 | C41: Insumo del modelo
A42: CAGR REAL | B42: =OPTIMIZACION!B18 -> 0.30046416 | C42: Lo que rindió de verdad ← reportar esto
A43: Volatilidad anual | B43: =OPTIMIZACION!B16 -> 0.18348151
A44: Sharpe (CAGR) | B44: =OPTIMIZACION!B20 -> 1.3841403 | C44: >1 muy bueno
A45: Beta vs XLE | B45: =OPTIMIZACION!B21 -> 0.56058611
...

Sheet PRECIOS
A1: PRECIOS DE CIERRE
A2: Pegá acá series nuevas manteniendo el orden de columnas.
A3: Fecha | B3: XOM | C3: SO | D3: VST | E3: ETN | F3: YPF | G3: WMB | H3: XLE | I3: XLU
A4: 44417 | B4: 53.4781 | C4: 61.1121 | D4: 18.034 | E4: 158.351 | F4: 4.48 | G4: 22.8172 | H4: 20.6235 | I4: 29.3926
A5: 44418 | B5: 54.3952 | C5: 61.4502 | D5: 17.652 | E5: 162.296 | F5: 4.74 | G5: 23.0205 | H5: 20.9869 | I5: 29.4238
A6: 44419 | B6: 54.5537 | C6: 61.8468 | D6: 17.5182 | E6: 161.864 | F6: 5.1 | G6: 23.0205 | H6: 21.1515 | I6: 29.6983
A7: 44420 | B7: 54.4302 | C7: 61.9314 | D7: 17.5562 | E7: 162.857 | F7: 5.04 | G7: 23.0378 | H7: 21.1308 | I7: 29.7281
A8: 44421 | B8: 53.8798 | C8: 62.3784 | D8: 17.566 | E8: 163.29 | F8: 4.87 | G8: 22.8817 | H8: 20.8811 | I8: 29.9381
A9: 44424 | B9: 53.0921 | C9: 63.188 | D9: 17.1644 | E9: 164.165 | F9: 4.8 | G9: 22.6783 | H9: 20.4971 | I9: 30.1208
A10: 44425 | B10: 52.7312 | C10: 63.2541 | D10: 17.3265 | E10: 162.591 | F10: 4.77 | G10: 22.5588 | H10: 20.2855 | I10: 30.1382
A11: 44426 | B11: 51.6216 | C11: 62.8362 | D11: 17.1927 | E11: 162.148 | F11: 4.6 | G11: 22.1531 | H11: 19.8633 | I11: 29.9858
A12: 44427 | B12: 50.0461 | C12: 63.188 | D12: 16.9934 | E12: 162.631 | F12: 4.4 | G12: 22.0153 | H12: 19.3477 | I12: 30.1079
A13: 44428 | B13: 50.0548 | C13: 64.0822 | D13: 17.3081 | E13: 163.132 | F13: 4.41 | G13: 22.1531 | H13: 19.3896 | I13: 30.4827
A14: 44431 | B14: 52.1147 | C14: 63.464 | D14: 17.2123 | E14: 164.489 | F14: 4.57 | G14: 22.5781 | H14: 20.1161 | I14: 30.0906
A15: 44432 | B15: 52.5416 | C15: 62.5689 | D15: 17.6129 | E15: 165.011 | F15: 4.84 | G15: 22.7073 | H15: 20.4503 | I15: 29.8944
... A1258: 46241 | B1258: 153.04 | C1258: 92.69 | D1258: 140.59 | E1258: 448.68 | F1258: 49.16 | G1258: 70.4 | H1258: 57.5 | I1258: 43.61

Sheet RETORNOS
A1: RETORNOS DIARIOS r = P(t) / P(t-1) − 1
A3: Fecha | B3: XOM | C3: SO | D3: VST | E3: ETN | F3: YPF | G3: WMB | H3: XLE | I3: XLU
A5: =IF(PRECIOS!A5="","",PRECIOS!A5) -> 44418 | B5: =IFERROR(IF(OR(PRECIOS!B5="",PRECIOS!B4=""),"",PRECIOS!B5/PRECIOS!B4-1),"") -> 0.017149076 | C5: =IFERROR(IF(OR(PRECIOS!C5="",PRECIOS!C4=""),"",PRECIOS!C5/PRECIOS!C4-1),"") -> 0.0055324559 | D5: =IFERROR(IF(OR(PRECIOS!D5="",PRECIOS!D4=""),"",PRECIOS!D5/PRECIOS!D4-1),"") -> -0.021182211 | E5: =IFERROR(IF(OR(PRECIOS!E5="",PRECIOS!E4=""),"",PRECIOS!E5/PRECIOS!E4-1),"") -> 0.02491301 | F5: =IFERROR(IF(OR(PRECIOS!F5="",PRECIOS!F4=""),"",PRECIOS!F5/PRECIOS!F4-1),"") -> 0.058035714 | G5: =IFERROR(IF(OR(PRECIOS!G5="",PRECIOS!G4=""),"",PRECIOS!G5/PRECIOS!G4-1),"") -> 0.0089099451 | H5: =IFERROR(IF(OR(PRECIOS!H5="",PRECIOS!H4=""),"",PRECIOS!H5/PRECIOS!H4-1),"") -> 0.017620675 | I5: =IFERROR(IF(OR(PRECIOS!I5="",PRECIOS!I4=""),"",PRECIOS!I5/PRECIOS!I4-1),"") -> 0.0010614917
A6: =IF(PRECIOS!A6="","",PRECIOS!A6) -> 44419 | B6: =IFERROR(IF(OR(PRECIOS!B6="",PRECIOS!B5=""),"",PRECIOS!B6/PRECIOS!B5-1),"") -> 0.00291386 | C6: =IFERROR(IF(OR(PRECIOS!C6="",PRECIOS!C5=""),"",PRECIOS!C6/PRECIOS!C5-1),"") -> 0.0064540067 | D6: =IFERROR(IF(OR(PRECIOS!D6="",PRECIOS!D5=""),"",PRECIOS!D6/PRECIOS!D5-1),"") -> -0.0075798776 | E6: =IFERROR(IF(OR(PRECIOS!E6="",PRECIOS!E5=""),"",PRECIOS!E6/PRECIOS!E5-1),"") -> -0.0026618031 | F6: =IFERROR(IF(OR(PRECIOS!F6="",PRECIOS!F5=""),"",PRECIOS!F6/PRECIOS!F5-1),"") -> 0.075949367 | G6: =IFERROR(IF(OR(PRECIOS!G6="",PRECIOS!G5=""),"",PRECIOS!G6/PRECIOS!G5-1),"") -> 0 | H6: =IFERROR(IF(OR(PRECIOS!H6="",PRECIOS!H5=""),"",PRECIOS!H6/PRECIOS!H5-1),"") -> 0.0078429878 | I6: =IFERROR(IF(OR(PRECIOS!I6="",PRECIOS!I5=""),"",PRECIOS!I6/PRECIOS!I5-1),"") -> 0.0093291825
A7: =IF(PRECIOS!A7="","",PRECIOS!A7) -> 44420 | B7: =IFERROR(IF(OR(PRECIOS!B7="",PRECIOS!B6=""),"",PRECIOS!B7/PRECIOS!B6-1),"") -> -0.0022638245 | C7: =IFERROR(IF(OR(PRECIOS!C7="",PRECIOS!C6=""),"",PRECIOS!C7/PRECIOS!C6-1),"") -> 0.0013678962 | D7: =IFERROR(IF(OR(PRECIOS!D7="",PRECIOS!D6=""),"",PRECIOS!D7/PRECIOS!D6-1),"") -> 0.0021691726 | E7: =IFERROR(IF(OR(PRECIOS!E7="",PRECIOS!E6=""),"",PRECIOS!E7/PRECIOS!E6-1),"") -> 0.0061347798 | F7: =IFERROR(IF(OR(PRECIOS!F7="",PRECIOS!F6=""),"",PRECIOS!F7/PRECIOS!F6-1),"") -> -0.011764706 | G7: =IFERROR(IF(OR(PRECIOS!G7="",PRECIOS!G6=""),"",PRECIOS!G7/PRECIOS!G6-1),"") -> 0.00075150409 | H7: =IFERROR(IF(OR(PRECIOS!H7="",PRECIOS!H6=""),"",PRECIOS!H7/PRECIOS!H6-1),"") -> -0.000978654 | I7: =IFERROR(IF(OR(PRECIOS!I7="",PRECIOS!I6=""),"",PRECIOS!I7/PRECIOS!I6-1),"") -> 0.0010034244
A8: =IF(PRECIOS!A8="","",PRECIOS!A8) -> 44421 | B8: =IFERROR(IF(OR(PRECIOS!B8="",PRECIOS!B7=""),"",PRECIOS!B8/PRECIOS!B7-1),"") -> -0.010112033 | C8: =IFERROR(IF(OR(PRECIOS!C8="",PRECIOS!C7=""),"",PRECIOS!C8/PRECIOS!C7-1),"") -> 0.0072176634 | D8: =IFERROR(IF(OR(PRECIOS!D8="",PRECIOS!D7=""),"",PRECIOS!D8/PRECIOS!D7-1),"") -> 0.00055820736 | E8: =IFERROR(IF(OR(PRECIOS!E8="",PRECIOS!E7=""),"",PRECIOS!E8/PRECIOS!E7-1),"") -> 0.0026587743 | F8: =IFERROR(IF(OR(PRECIOS!F8="",PRECIOS!F7=""),"",PRECIOS!F8/PRECIOS!F7-1),"") -> -0.033730159 | G8: =IFERROR(IF(OR(PRECIOS!G8="",PRECIOS!G7=""),"",PRECIOS!G8/PRECIOS!G7-1),"") -> -0.0067758206 | H8: =IFERROR(IF(OR(PRECIOS!H8="",PRECIOS!H7=""),"",PRECIOS!H8/PRECIOS!H7-1),"") -> -0.011816874 | I8: =IFERROR(IF(OR(PRECIOS!I8="",PRECIOS!I7=""),"",PRECIOS!I8/PRECIOS!I7-1),"") -> 0.0070640236
A9: =IF(PRECIOS!A9="","",PRECIOS!A9) -> 44424 | B9: =IFERROR(IF(OR(PRECIOS!B9="",PRECIOS!B8=""),"",PRECIOS!B9/PRECIOS!B8-1),"") -> -0.014619579 | C9: =IFERROR(IF(OR(PRECIOS!C9="",PRECIOS!C8=""),"",PRECIOS!C9/PRECIOS!C8-1),"") -> 0.012978852 | D9: =IFERROR(IF(OR(PRECIOS!D9="",PRECIOS!D8=""),"",PRECIOS!D9/PRECIOS!D8-1),"") -> -0.022862348 | E9: =IFERROR(IF(OR(PRECIOS!E9="",PRECIOS!E8=""),"",PRECIOS!E9/PRECIOS!E8-1),"") -> 0.0053585645 | F9: =IFERROR(IF(OR(PRECIOS!F9="",PRECIOS!F8=""),"",PRECIOS!F9/PRECIOS!F8-1),"") -> -0.014373717 | G9: =IFERROR(IF(OR(PRECIOS!G9="",PRECIOS!G8=""),"",PRECIOS!G9/PRECIOS!G8-1),"") -> -0.0088891997 | H9: =IFERROR(IF(OR(PRECIOS!H9="",PRECIOS!H8=""),"",PRECIOS!H9/PRECIOS!H8-1),"") -> -0.018389836 | I9: =IFERROR(IF(OR(PRECIOS!I9="",PRECIOS!I8=""),"",PRECIOS!I9/PRECIOS!I8-1),"") -> 0.0061025917
A10: =IF(PRECIOS!A10="","",PRECIOS!A10) -> 44425 | B10: =IFERROR(IF(OR(PRECIOS!B10="",PRECIOS!B9=""),"",PRECIOS!B10/PRECIOS!B9-1),"") -> -0.0067976215 | C10: =IFERROR(IF(OR(PRECIOS!C10="",PRECIOS!C9=""),"",PRECIOS!C10/PRECIOS!C9-1),"") -> 0.0010460847 | D10: =IFERROR(IF(OR(PRECIOS!D10="",PRECIOS!D9=""),"",PRECIOS!D10/PRECIOS!D9-1),"") -> 0.0094439654 | E10: =IFERROR(IF(OR(PRECIOS!E10="",PRECIOS!E9=""),"",PRECIOS!E10/PRECIOS!E9-1),"") -> -0.0095879146 | F10: =IFERROR(IF(OR(PRECIOS!F10="",PRECIOS!F9=""),"",PRECIOS!F10/PRECIOS!F9-1),"") -> -0.00625 | G10: =IFERROR(IF(OR(PRECIOS!G10="",PRECIOS!G9=""),"",PRECIOS!G10/PRECIOS!G9-1),"") -> -0.0052693544 | H10: =IFERROR(IF(OR(PRECIOS!H10="",PRECIOS!H9=""),"",PRECIOS!H10/PRECIOS!H9-1),"") -> -0.010323412 | I10: =IFERROR(IF(OR(PRECIOS!I10="",PRECIOS!I9=""),"",PRECIOS!I10/PRECIOS!I9-1),"") -> 0.0005776739
A11: =IF(PRECIOS!A11="","",PRECIOS!A11) -> 44426 | B11: =IFERROR(IF(OR(PRECIOS!B11="",PRECIOS!B10=""),"",PRECIOS!B11/PRECIOS!B10-1),"") -> -0.021042571 | C11: =IFERROR(IF(OR(PRECIOS!C11="",PRECIOS!C10=""),"",PRECIOS!C11/PRECIOS!C10-1),"") -> -0.0066066864 | D11: =IFERROR(IF(OR(PRECIOS!D11="",PRECIOS!D10=""),"",PRECIOS!D11/PRECIOS!D10-1),"") -> -0.0077222751 | E11: =IFERROR(IF(OR(PRECIOS!E11="",PRECIOS!E10=""),"",PRECIOS!E11/PRECIOS!E10-1),"") -> -0.0027246281 | F11: =IFERROR(IF(OR(PRECIOS!F11="",PRECIOS!F10=""),"",PRECIOS!F11/PRECIOS!F10-1),"") -> -0.035639413 | G11: =IFERROR(IF(OR(PRECIOS!G11="",PRECIOS!G10=""),"",PRECIOS!G11/PRECIOS!G10-1),"") -> -0.017984113 | H11: =IFERROR(IF(OR(PRECIOS!H11="",PRECIOS!H10=""),"",PRECIOS!H11/PRECIOS!H10-1),"") -> -0.020812896 | I11: =IFERROR(IF(OR(PRECIOS!I11="",PRECIOS!I10=""),"",PRECIOS!I11/PRECIOS!I10-1),"") -> -0.0050567054
A12: =IF(PRECIOS!A12="","",PRECIOS!A12) -> 44427 | B12: =IFERROR(IF(OR(PRECIOS!B12="",PRECIOS!B11=""),"",PRECIOS!B12/PRECIOS!B11-1),"") -> -0.03052017 | C12: =IFERROR(IF(OR(PRECIOS!C12="",PRECIOS!C11=""),"",PRECIOS!C12/PRECIOS!C11-1),"") -> 0.0055986836 | D12: =IFERROR(IF(OR(PRECIOS!D12="",PRECIOS!D11=""),"",PRECIOS!D12/PRECIOS!D11-1),"") -> -0.011592129 | E12: =IFERROR(IF(OR(PRECIOS!E12="",PRECIOS!E11=""),"",PRECIOS!E12/PRECIOS!E11-1),"") -> 0.0029787601 | F12: =IFERROR(IF(OR(PRECIOS!F12="",PRECIOS!F11=""),"",PRECIOS!F12/PRECIOS!F11-1),"") -> -0.043478261 | G12: =IFERROR(IF(OR(PRECIOS!G12="",PRECIOS!G11=""),"",PRECIOS!G12/PRECIOS!G11-1),"") -> -0.0062203484 | H12: =IFERROR(IF(OR(PRECIOS!H12="",PRECIOS!H11=""),"",PRECIOS!H12/PRECIOS!H11-1),"") -> -0.025957419 | I12: =IFERROR(IF(OR(PRECIOS!I12="",PRECIOS!I11=""),"",PRECIOS!I12/PRECIOS!I11-1),"") -> 0.0040719274
A13: =IF(PRECIOS!A13="","",PRECIOS!A13) -> 44428 | B13: =IFERROR(IF(OR(PRECIOS!B13="",PRECIOS!B12=""),"",PRECIOS!B13/PRECIOS!B12-1),"") -> 0.00017383972 | C13: =IFERROR(IF(OR(PRECIOS!C13="",PRECIOS!C12=""),"",PRECIOS!C13/PRECIOS!C12-1),"") -> 0.014151421 | D13: =IFERROR(IF(OR(PRECIOS!D13="",PRECIOS!D12=""),"",PRECIOS!D13/PRECIOS!D12-1),"") -> 0.018518954 | E13: =IFERROR(IF(OR(PRECIOS!E13="",PRECIOS!E12=""),"",PRECIOS!E13/PRECIOS!E12-1),"") -> 0.0030805935 | F13: =IFERROR(IF(OR(PRECIOS!F13="",PRECIOS!F12=""),"",PRECIOS!F13/PRECIOS!F12-1),"") -> 0.0022727273 | G13: =IFERROR(IF(OR(PRECIOS!G13="",PRECIOS!G12=""),"",PRECIOS!G13/PRECIOS!G12-1),"") -> 0.0062592833 | H13: =IFERROR(IF(OR(PRECIOS!H13="",PRECIOS!H12=""),"",PRECIOS!H13/PRECIOS!H12-1),"") -> 0.0021656321 | I13: =IFERROR(IF(OR(PRECIOS!I13="",PRECIOS!I12=""),"",PRECIOS!I13/PRECIOS!I12-1),"") -> 0.01244856
A14: =IF(PRECIOS!A14="","",PRECIOS!A14) -> 44431 | B14: =IFERROR(IF(OR(PRECIOS!B14="",PRECIOS!B13=""),"",PRECIOS!B14/PRECIOS!B13-1),"") -> 0.041152896 | C14: =IFERROR(IF(OR(PRECIOS!C14="",PRECIOS!C13=""),"",PRECIOS!C14/PRECIOS!C13-1),"") -> -0.0096469847 | D14: =IFERROR(IF(OR(PRECIOS!D14="",PRECIOS!D13=""),"",PRECIOS!D14/PRECIOS!D13-1),"") -> -0.0055349807 | E14: =IFERROR(IF(OR(PRECIOS!E14="",PRECIOS!E13=""),"",PRECIOS!E14/PRECIOS!E13-1),"") -> 0.008318417 | F14: =IFERROR(IF(OR(PRECIOS!F14="",PRECIOS!F13=""),"",PRECIOS!F14/PRECIOS!F13-1),"") -> 0.036281179 | G14: =IFERROR(IF(OR(PRECIOS!G14="",PRECIOS!G13=""),"",PRECIOS!G14/PRECIOS!G13-1),"") -> 0.019184674 | H14: =IFERROR(IF(OR(PRECIOS!H14="",PRECIOS!H13=""),"",PRECIOS!H14/PRECIOS!H13-1),"") -> 0.03746854 | I14: =IFERROR(IF(OR(PRECIOS!I14="",PRECIOS!I13=""),"",PRECIOS!I14/PRECIOS!I13-1),"") -> -0.012863034
A15: =IF(PRECIOS!A15="","",PRECIOS!A15) -> 44432 | B15: =IFERROR(IF(OR(PRECIOS!B15="",PRECIOS!B14=""),"",PRECIOS!B15/PRECIOS!B14-1),"") -> 0.0081915467 | C15: =IFERROR(IF(OR(PRECIOS!C15="",PRECIOS!C14=""),"",PRECIOS!C15/PRECIOS!C14-1),"") -> -0.014104059 | D15: =IFERROR(IF(OR(PRECIOS!D15="",PRECIOS!D14=""),"",PRECIOS!D15/PRECIOS!D14-1),"") -> 0.023274054 | E15: =IFERROR(IF(OR(PRECIOS!E15="",PRECIOS!E14=""),"",PRECIOS!E15/PRECIOS!E14-1),"") -> 0.0031734645 | F15: =IFERROR(IF(OR(PRECIOS!F15="",PRECIOS!F14=""),"",PRECIOS!F15/PRECIOS!F14-1),"") -> 0.059080963 | G15: =IFERROR(IF(OR(PRECIOS!G15="",PRECIOS!G14=""),"",PRECIOS!G15/PRECIOS!G14-1),"") -> 0.0057223593 | H15: =IFERROR(IF(OR(PRECIOS!H15="",PRECIOS!H14=""),"",PRECIOS!H15/PRECIOS!H14-1),"") -> 0.016613558 | I15: =IFERROR(IF(OR(PRECIOS!I15="",PRECIOS!I14=""),"",PRECIOS!I15/PRECIOS!I14-1),"") -> -0.0065203087
A16: =IF(PRECIOS!A16="","",PRECIOS!A16) -> 44433 | B16: =IFERROR(IF(OR(PRECIOS!B16="",PRECIOS!B15=""),"",PRECIOS!B16/PRECIOS!B15-1),"") -> 0.0018138009 | C16: =IFERROR(IF(OR(PRECIOS!C16="",PRECIOS!C15=""),"",PRECIOS!C16/PRECIOS!C15-1),"") -> 0.0021288532 | D16: =IFERROR(IF(OR(PRECIOS!D16="",PRECIOS!D15=""),"",PRECIOS!D16/PRECIOS!D15-1),"") -> 0.029841764 | E16: =IFERROR(IF(OR(PRECIOS!E16="",PRECIOS!E15=""),"",PRECIOS!E16/PRECIOS!E15-1),"") -> 0.0048905831 | F16: =IFERROR(IF(OR(PRECIOS!F16="",PRECIOS!F15=""),"",PRECIOS!F16/PRECIOS!F15-1),"") -> 0.033057851 | G16: =IFERROR(IF(OR(PRECIOS!G16="",PRECIOS!G15=""),"",PRECIOS!G16/PRECIOS!G15-1),"") -> -0.0020786267 | H16: =IFERROR(IF(OR(PRECIOS!H16="",PRECIOS!H15=""),"",PRECIOS!H16/PRECIOS!H15-1),"") -> 0.0076575894 | I16: =IFERROR(IF(OR(PRECIOS!I16="",PRECIOS!I15=""),"",PRECIOS!I16/PRECIOS!I15-1),"") -> 0.0018899861
... A1300: =IF(PRECIOS!A1300="","",PRECIOS!A1300) | B1300: =IFERROR(IF(OR(PRECIOS!B1300="",PRECIOS!B1299=""),"",PRECIOS!B1300/PRECIOS!B1299-1),"") | C1300: =IFERROR(IF(OR(PRECIOS!C1300="",PRECIOS!C1299=""),"",PRECIOS!C1300/PRECIOS!C1299-1),"") | D1300: =IFERROR(IF(OR(PRECIOS!D1300="",PRECIOS!D1299=""),"",PRECIOS!D1300/PRECIOS!D1299-1),"") | E1300: =IFERROR(IF(OR(PRECIOS!E1300="",PRECIOS!E1299=""),"",PRECIOS!E1300/PRECIOS!E1299-1),"") | F1300: =IFERROR(IF(OR(PRECIOS!F1300="",PRECIOS!F1299=""),"",PRECIOS!F1300/PRECIOS!F1299-1),"") | G1300: =IFERROR(IF(OR(PRECIOS!G1300="",PRECIOS!G1299=""),"",PRECIOS!G1300/PRECIOS!G1299-1),"") | H1300: =IFERROR(IF(OR(PRECIOS!H1300="",PRECIOS!H1299=""),"",PRECIOS!H1300/PRECIOS!H1299-1),"") | I1300: =IFERROR(IF(OR(PRECIOS!I1300="",PRECIOS!I1299=""),"",PRECIOS!I1300/PRECIOS!I1299-1),"")

Sheet CORRELACION
A1: MATRIZ DE CORRELACIÓN
A2: ρ = Cov(A,B) / (σA · σB). Verde = diversifica. Rojo = redundante.
B4: XOM | C4: SO | D4: VST | E4: ETN | F4: YPF | G4: WMB | H4: XLE | I4: XLU
A5: XOM | B5: =IFERROR(CORREL(RETORNOS!$B$5:$B$1300,RETORNOS!$B$5:$B$1300),"") -> 1 | C5: =IFERROR(CORREL(RETORNOS!$B$5:$B$1300,RETORNOS!$C$5:$C$1300),"") -> 0.17826173 | D5: =IFERROR(CORREL(RETORNOS!$B$5:$B$1300,RETORNOS!$D$5:$D$1300),"") -> 0.13508272 | E5: =IFERROR(CORREL(RETORNOS!$B$5:$B$1300,RETORNOS!$E$5:$E$1300),"") -> 0.12343929 | F5: =IFERROR(CORREL(RETORNOS!$B$5:$B$1300,RETORNOS!$F$5:$F$1300),"") -> 0.37204594 | G5: =IFERROR(CORREL(RETORNOS!$B$5:$B$1300,RETORNOS!$G$5:$G$1300),"") -> 0.51763884 | H5: =IFERROR(CORREL(RETORNOS!$B$5:$B$1300,RETORNOS!$H$5:$H$1300),"") -> 0.92342681 | I5: =IFERROR(CORREL(RETORNOS!$B$5:$B$1300,RETORNOS!$I$5:$I$1300),"") -> 0.21004486 | K5: CÓMO LEERLA
A6: SO | B6: =IFERROR(CORREL(RETORNOS!$C$5:$C$1300,RETORNOS!$B$5:$B$1300),"") -> 0.17826173 | C6: =IFERROR(CORREL(RETORNOS!$C$5:$C$1300,RETORNOS!$C$5:$C$1300),"") -> 1 | D6: =IFERROR(CORREL(RETORNOS!$C$5:$C$1300,RETORNOS!$D$5:$D$1300),"") -> 0.096933909 | E6: =IFERROR(CORREL(RETORNOS!$C$5:$C$1300,RETORNOS!$E$5:$E$1300),"") -> 0.033448647 | F6: =IFERROR(CORREL(RETORNOS!$C$5:$C$1300,RETORNOS!$F$5:$F$1300),"") -> 0.063823201 | G6: =IFERROR(CORREL(RETORNOS!$C$5:$C$1300,RETORNOS!$G$5:$G$1300),"") -> 0.3158032 | H6: =IFERROR(CORREL(RETORNOS!$C$5:$C$1300,RETORNOS!$H$5:$H$1300),"") -> 0.1819555 | I6: =IFERROR(CORREL(RETORNOS!$C$5:$C$1300,RETORNOS!$I$5:$I$1300),"") -> 0.81831082 | K6: < 0,30 diversifican de verdad
A7: VST | B7: =IFERROR(CORREL(RETORNOS!$D$5:$D$1300,RETORNOS!$B$5:$B$1300),"") -> 0.13508272 | C7: =IFERROR(CORREL(RETORNOS!$D$5:$D$1300,RETORNOS!$C$5:$C$1300),"") -> 0.096933909 | D7: =IFERROR(CORREL(RETORNOS!$D$5:$D$1300,RETORNOS!$D$5:$D$1300),"") -> 1 | E7: =IFERROR(CORREL(RETORNOS!$D$5:$D$1300,RETORNOS!$E$5:$E$1300),"") -> 0.53010487 | F7: =IFERROR(CORREL(RETORNOS!$D$5:$D$1300,RETORNOS!$F$5:$F$1300),"") -> 0.21298057 | G7: =IFERROR(CORREL(RETORNOS!$D$5:$D$1300,RETORNOS!$G$5:$G$1300),"") -> 0.36888081 | H7: =IFERROR(CORREL(RETORNOS!$D$5:$D$1300,RETORNOS!$H$5:$H$1300),"") -> 0.24241404 | I7: =IFERROR(CORREL(RETORNOS!$D$5:$D$1300,RETORNOS!$I$5:$I$1300),"") -> 0.42585737 | K7: 0,30-0,70 normal dentro de un sector
A8: ETN | B8: =IFERROR(CORREL(RETORNOS!$E$5:$E$1300,RETORNOS!$B$5:$B$1300),"") -> 0.12343929 | C8: =IFERROR(CORREL(RETORNOS!$E$5:$E$1300,RETORNOS!$C$5:$C$1300),"") -> 0.033448647 | D8: =IFERROR(CORREL(RETORNOS!$E$5:$E$1300,RETORNOS!$D$5:$D$1300),"") -> 0.53010487 | E8: =IFERROR(CORREL(RETORNOS!$E$5:$E$1300,RETORNOS!$E$5:$E$1300),"") -> 1 | F8: =IFERROR(CORREL(RETORNOS!$E$5:$E$1300,RETORNOS!$F$5:$F$1300),"") -> 0.23358594 | G8: =IFERROR(CORREL(RETORNOS!$E$5:$E$1300,RETORNOS!$G$5:$G$1300),"") -> 0.31448513 | H8: =IFERROR(CORREL(RETORNOS!$E$5:$E$1300,RETORNOS!$H$5:$H$1300),"") -> 0.23505253 | I8: =IFERROR(CORREL(RETORNOS!$E$5:$E$1300,RETORNOS!$I$5:$I$1300),"") -> 0.2957107 | K8: > 0,85 redundancia: sacá uno
A9: YPF | B9: =IFERROR(CORREL(RETORNOS!$F$5:$F$1300,RETORNOS!$B$5:$B$1300),"") -> 0.37204594 | C9: =IFERROR(CORREL(RETORNOS!$F$5:$F$1300,RETORNOS!$C$5:$C$1300),"") -> 0.063823201 | D9: =IFERROR(CORREL(RETORNOS!$F$5:$F$1300,RETORNOS!$D$5:$D$1300),"") -> 0.21298057 | E9: =IFERROR(CORREL(RETORNOS!$F$5:$F$1300,RETORNOS!$E$5:$E$1300),"") -> 0.23358594 | F9: =IFERROR(CORREL(RETORNOS!$F$5:$F$1300,RETORNOS!$F$5:$F$1300),"") -> 1 | G9: =IFERROR(CORREL(RETORNOS!$F$5:$F$1300,RETORNOS!$G$5:$G$1300),"") -> 0.28168029 | H9: =IFERROR(CORREL(RETORNOS!$F$5:$F$1300,RETORNOS!$H$5:$H$1300),"") -> 0.4408752 | I9: =IFERROR(CORREL(RETORNOS!$F$5:$F$1300,RETORNOS!$I$5:$I$1300),"") -> 0.15918567
A10: WMB | B10: =IFERROR(CORREL(RETORNOS!$G$5:$G$1300,RETORNOS!$B$5:$B$1300),"") -> 0.51763884 | C10: =IFERROR(CORREL(RETORNOS!$G$5:$G$1300,RETORNOS!$C$5:$C$1300),"") -> 0.3158032 | D10: =IFERROR(CORREL(RETORNOS!$G$5:$G$1300,RETORNOS!$D$5:$D$1300),"") -> 0.36888081 | E10: =IFERROR(CORREL(RETORNOS!$G$5:$G$1300,RETORNOS!$E$5:$E$1300),"") -> 0.31448513 | F10: =IFERROR(CORREL(RETORNOS!$G$5:$G$1300,RETORNOS!$F$5:$F$1300),"") -> 0.28168029 | G10: =IFERROR(CORREL(RETORNOS!$G$5:$G$1300,RETORNOS!$G$5:$G$1300),"") -> 1 | H10: =IFERROR(CORREL(RETORNOS!$G$5:$G$1300,RETORNOS!$H$5:$H$1300),"") -> 0.64968125 | I10: =IFERROR(CORREL(RETORNOS!$G$5:$G$1300,RETORNOS!$I$5:$I$1300),"") -> 0.44271319 | K10: Tu resultado: media 0,25
A11: XLE | B11: =IFERROR(CORREL(RETORNOS!$H$5:$H$1300,RETORNOS!$B$5:$B$1300),"") -> 0.92342681 | C11: =IFERROR(CORREL(RETORNOS!$H$5:$H$1300,RETORNOS!$C$5:$C$1300),"") -> 0.1819555 | D11: =IFERROR(CORREL(RETORNOS!$H$5:$H$1300,RETORNOS!$D$5:$D$1300),"") -> 0.24241404 | E11: =IFERROR(CORREL(RETORNOS!$H$5:$H$1300,RETORNOS!$E$5:$E$1300),"") -> 0.23505253 | F11: =IFERROR(CORREL(RETORNOS!$H$5:$H$1300,RETORNOS!$F$5:$F$1300),"") -> 0.4408752 | G11: =IFERROR(CORREL(RETORNOS!$H$5:$H$1300,RETORNOS!$G$5:$G$1300),"") -> 0.64968125 | H11: =IFERROR(CORREL(RETORNOS!$H$5:$H$1300,RETORNOS!$H$5:$H$1300),"") -> 1 | I11: =IFERROR(CORREL(RETORNOS!$H$5:$H$1300,RETORNOS!$I$5:$I$1300),"") -> 0.26659834 | K11: Par más alto: VST-ETN 0,53
A12: XLU | B12: =IFERROR(CORREL(RETORNOS!$I$5:$I$1300,RETORNOS!$B$5:$B$1300),"") -> 0.21004486 | C12: =IFERROR(CORREL(RETORNOS!$I$5:$I$1300,RETORNOS!$C$5:$C$1300),"") -> 0.81831082 | D12: =IFERROR(CORREL(RETORNOS!$I$5:$I$1300,RETORNOS!$D$5:$D$1300),"") -> 0.42585737 | E12: =IFERROR(CORREL(RETORNOS!$I$5:$I$1300,RETORNOS!$E$5:$E$1300),"") -> 0.2957107 | F12: =IFERROR(CORREL(RETORNOS!$I$5:$I$1300,RETORNOS!$F$5:$F$1300),"") -> 0.15918567 | G12: =IFERROR(CORREL(RETORNOS!$I$5:$I$1300,RETORNOS!$G$5:$G$1300),"") -> 0.44271319 | H12: =IFERROR(CORREL(RETORNOS!$I$5:$I$1300,RETORNOS!$H$5:$H$1300),"") -> 0.26659834 | I12: =IFERROR(CORREL(RETORNOS!$I$5:$I$1300,RETORNOS!$I$5:$I$1300),"") -> 1 | K12: Par más bajo: SO-ETN 0,03
K14: En el peor decil de días,
A15: Correlación media (6 activos) | B15: =IFERROR((SUM(B5:G10)-6)/30,"") -> 0.25187967 | C15: (suma de las 36 celdas − 6 de la diagonal) / 30 | K15: VST-ETN sube de 0,40 a 0,59.
K16: La diversificación se reduce en el estrés.

Sheet COVARIANZA
A1: MATRIZ DE COVARIANZAS (diaria)
A2: Cov = ρ · σA · σB. Es la correlación sin normalizar: lo que consume el optimizador.
B4: XOM | C4: SO | D4: VST | E4: ETN | F4: YPF | G4: WMB | H4: XLE | I4: XLU
A5: XOM | B5: =IFERROR(_xlfn.COVARIANCE.S(RETORNOS!$B$5:$B$1300,RETORNOS!$B$5:$B$1300),"") -> 0.00028311329 | C5: =IFERROR(_xlfn.COVARIANCE.S(RETORNOS!$B$5:$B$1300,RETORNOS!$C$5:$C$1300),"") -> 3.5394774e-05 | D5: =IFERROR(_xlfn.COVARIANCE.S(RETORNOS!$B$5:$B$1300,RETORNOS!$D$5:$D$1300),"") -> 6.916029e-05 | E5: =IFERROR(_xlfn.COVARIANCE.S(RETORNOS!$B$5:$B$1300,RETORNOS!$E$5:$E$1300),"") -> 4.1065615e-05 | F5: =IFERROR(_xlfn.COVARIANCE.S(RETORNOS!$B$5:$B$1300,RETORNOS!$F$5:$F$1300),"") -> 0.00021494828 | G5: =IFERROR(_xlfn.COVARIANCE.S(RETORNOS!$B$5:$B$1300,RETORNOS!$G$5:$G$1300),"") -> 0.00013115737 | H5: =IFERROR(_xlfn.COVARIANCE.S(RETORNOS!$B$5:$B$1300,RETORNOS!$H$5:$H$1300),"") -> 0.00025205555 | I5: =IFERROR(_xlfn.COVARIANCE.S(RETORNOS!$B$5:$B$1300,RETORNOS!$I$5:$I$1300),"") -> 3.8600903e-05
A6: SO | B6: =IFERROR(_xlfn.COVARIANCE.S(RETORNOS!$C$5:$C$1300,RETORNOS!$B$5:$B$1300),"") -> 3.5394774e-05 | C6: =IFERROR(_xlfn.COVARIANCE.S(RETORNOS!$C$5:$C$1300,RETORNOS!$C$5:$C$1300),"") -> 0.00013925211 | D6: =IFERROR(_xlfn.COVARIANCE.S(RETORNOS!$C$5:$C$1300,RETORNOS!$D$5:$D$1300),"") -> 3.4805949e-05 | E6: =IFERROR(_xlfn.COVARIANCE.S(RETORNOS!$C$5:$C$1300,RETORNOS!$E$5:$E$1300),"") -> 7.8041254e-06 | F6: =IFERROR(_xlfn.COVARIANCE.S(RETORNOS!$C$5:$C$1300,RETORNOS!$F$5:$F$1300),"") -> 2.586049e-05 | G6: =IFERROR(_xlfn.COVARIANCE.S(RETORNOS!$C$5:$C$1300,RETORNOS!$G$5:$G$1300),"") -> 5.6118121e-05 | H6: =IFERROR(_xlfn.COVARIANCE.S(RETORNOS!$C$5:$C$1300,RETORNOS!$H$5:$H$1300),"") -> 3.4832105e-05 | I6: =IFERROR(_xlfn.COVARIANCE.S(RETORNOS!$C$5:$C$1300,RETORNOS!$I$5:$I$1300),"") -> 0.00010546891
A7: VST | B7: =IFERROR(_xlfn.COVARIANCE.S(RETORNOS!$D$5:$D$1300,RETORNOS!$B$5:$B$1300),"") -> 6.916029e-05 | C7: =IFERROR(_xlfn.COVARIANCE.S(RETORNOS!$D$5:$D$1300,RETORNOS!$C$5:$C$1300),"") -> 3.4805949e-05 | D7: =IFERROR(_xlfn.COVARIANCE.S(RETORNOS!$D$5:$D$1300,RETORNOS!$D$5:$D$1300),"") -> 0.00092587791 | E7: =IFERROR(_xlfn.COVARIANCE.S(RETORNOS!$D$5:$D$1300,RETORNOS!$E$5:$E$1300),"") -> 0.00031892125 | F7: =IFERROR(_xlfn.COVARIANCE.S(RETORNOS!$D$5:$D$1300,RETORNOS!$F$5:$F$1300),"") -> 0.00022252259 | G7: =IFERROR(_xlfn.COVARIANCE.S(RETORNOS!$D$5:$D$1300,RETORNOS!$G$5:$G$1300),"") -> 0.0001690241 | H7: =IFERROR(_xlfn.COVARIANCE.S(RETORNOS!$D$5:$D$1300,RETORNOS!$H$5:$H$1300),"") -> 0.0001196598 | I7: =IFERROR(_xlfn.COVARIANCE.S(RETORNOS!$D$5:$D$1300,RETORNOS!$I$5:$I$1300),"") -> 0.00014152928
A8: ETN | B8: =IFERROR(_xlfn.COVARIANCE.S(RETORNOS!$E$5:$E$1300,RETORNOS!$B$5:$B$1300),"") -> 4.1065615e-05 | C8: =IFERROR(_xlfn.COVARIANCE.S(RETORNOS!$E$5:$E$1300,RETORNOS!$C$5:$C$1300),"") -> 7.8041254e-06 | D8: =IFERROR(_xlfn.COVARIANCE.S(RETORNOS!$E$5:$E$1300,RETORNOS!$D$5:$D$1300),"") -> 0.00031892125 | E8: =IFERROR(_xlfn.COVARIANCE.S(RETORNOS!$E$5:$E$1300,RETORNOS!$E$5:$E$1300),"") -> 0.00039092155 | F8: =IFERROR(_xlfn.COVARIANCE.S(RETORNOS!$E$5:$E$1300,RETORNOS!$F$5:$F$1300),"") -> 0.00015858013 | G8: =IFERROR(_xlfn.COVARIANCE.S(RETORNOS!$E$5:$E$1300,RETORNOS!$G$5:$G$1300),"") -> 9.3633365e-05 | H8: =IFERROR(_xlfn.COVARIANCE.S(RETORNOS!$E$5:$E$1300,RETORNOS!$H$5:$H$1300),"") -> 7.5391674e-05 | I8: =IFERROR(_xlfn.COVARIANCE.S(RETORNOS!$E$5:$E$1300,RETORNOS!$I$5:$I$1300),"") -> 6.3858267e-05
A9: YPF | B9: =IFERROR(_xlfn.COVARIANCE.S(RETORNOS!$F$5:$F$1300,RETORNOS!$B$5:$B$1300),"") -> 0.00021494828 | C9: =IFERROR(_xlfn.COVARIANCE.S(RETORNOS!$F$5:$F$1300,RETORNOS!$C$5:$C$1300),"") -> 2.586049e-05 | D9: =IFERROR(_xlfn.COVARIANCE.S(RETORNOS!$F$5:$F$1300,RETORNOS!$D$5:$D$1300),"") -> 0.00022252259 | E9: =IFERROR(_xlfn.COVARIANCE.S(RETORNOS!$F$5:$F$1300,RETORNOS!$E$5:$E$1300),"") -> 0.00015858013 | F9: =IFERROR(_xlfn.COVARIANCE.S(RETORNOS!$F$5:$F$1300,RETORNOS!$F$5:$F$1300),"") -> 0.001179002 | G9: =IFERROR(_xlfn.COVARIANCE.S(RETORNOS!$F$5:$F$1300,RETORNOS!$G$5:$G$1300),"") -> 0.00014564629 | H9: =IFERROR(_xlfn.COVARIANCE.S(RETORNOS!$F$5:$F$1300,RETORNOS!$H$5:$H$1300),"") -> 0.00024557638 | I9: =IFERROR(_xlfn.COVARIANCE.S(RETORNOS!$F$5:$F$1300,RETORNOS!$I$5:$I$1300),"") -> 5.9698929e-05
A10: WMB | B10: =IFERROR(_xlfn.COVARIANCE.S(RETORNOS!$G$5:$G$1300,RETORNOS!$B$5:$B$1300),"") -> 0.00013115737 | C10: =IFERROR(_xlfn.COVARIANCE.S(RETORNOS!$G$5:$G$1300,RETORNOS!$C$5:$C$1300),"") -> 5.6118121e-05 | D10: =IFERROR(_xlfn.COVARIANCE.S(RETORNOS!$G$5:$G$1300,RETORNOS!$D$5:$D$1300),"") -> 0.0001690241 | E10: =IFERROR(_xlfn.COVARIANCE.S(RETORNOS!$G$5:$G$1300,RETORNOS!$E$5:$E$1300),"") -> 9.3633365e-05 | F10: =IFERROR(_xlfn.COVARIANCE.S(RETORNOS!$G$5:$G$1300,RETORNOS!$F$5:$F$1300),"") -> 0.00014564629 | G10: =IFERROR(_xlfn.COVARIANCE.S(RETORNOS!$G$5:$G$1300,RETORNOS!$G$5:$G$1300),"") -> 0.0002267626 | H10: =IFERROR(_xlfn.COVARIANCE.S(RETORNOS!$G$5:$G$1300,RETORNOS!$H$5:$H$1300),"") -> 0.00015870832 | I10: =IFERROR(_xlfn.COVARIANCE.S(RETORNOS!$G$5:$G$1300,RETORNOS!$I$5:$I$1300),"") -> 7.2813759e-05
A11: XLE | B11: =IFERROR(_xlfn.COVARIANCE.S(RETORNOS!$H$5:$H$1300,RETORNOS!$B$5:$B$1300),"") -> 0.00025205555 | C11: =IFERROR(_xlfn.COVARIANCE.S(RETORNOS!$H$5:$H$1300,RETORNOS!$C$5:$C$1300),"") -> 3.4832105e-05 | D11: =IFERROR(_xlfn.COVARIANCE.S(RETORNOS!$H$5:$H$1300,RETORNOS!$D$5:$D$1300),"") -> 0.0001196598 | E11: =IFERROR(_xlfn.COVARIANCE.S(RETORNOS!$H$5:$H$1300,RETORNOS!$E$5:$E$1300),"") -> 7.5391674e-05 | F11: =IFERROR(_xlfn.COVARIANCE.S(RETORNOS!$H$5:$H$1300,RETORNOS!$F$5:$F$1300),"") -> 0.00024557638 | G11: =IFERROR(_xlfn.COVARIANCE.S(RETORNOS!$H$5:$H$1300,RETORNOS!$G$5:$G$1300),"") -> 0.00015870832 | H11: =IFERROR(_xlfn.COVARIANCE.S(RETORNOS!$H$5:$H$1300,RETORNOS!$H$5:$H$1300),"") -> 0.0002631645 | I11: =IFERROR(_xlfn.COVARIANCE.S(RETORNOS!$H$5:$H$1300,RETORNOS!$I$5:$I$1300),"") -> 4.7236354e-05
A12: XLU | B12: =IFERROR(_xlfn.COVARIANCE.S(RETORNOS!$I$5:$I$1300,RETORNOS!$B$5:$B$1300),"") -> 3.8600903e-05 | C12: =IFERROR(_xlfn.COVARIANCE.S(RETORNOS!$I$5:$I$1300,RETORNOS!$C$5:$C$1300),"") -> 0.00010546891 | D12: =IFERROR(_xlfn.COVARIANCE.S(RETORNOS!$I$5:$I$1300,RETORNOS!$D$5:$D$1300),"") -> 0.00014152928 | E12: =IFERROR(_xlfn.COVARIANCE.S(RETORNOS!$I$5:$I$1300,RETORNOS!$E$5:$E$1300),"") -> 6.3858267e-05 | F12: =IFERROR(_xlfn.COVARIANCE.S(RETORNOS!$I$5:$I$1300,RETORNOS!$F$5:$F$1300),"") -> 5.9698929e-05 | G12: =IFERROR(_xlfn.COVARIANCE.S(RETORNOS!$I$5:$I$1300,RETORNOS!$G$5:$G$1300),"") -> 7.2813759e-05 | H12: =IFERROR(_xlfn.COVARIANCE.S(RETORNOS!$I$5:$I$1300,RETORNOS!$H$5:$H$1300),"") -> 4.7236354e-05 | I12: =IFERROR(_xlfn.COVARIANCE.S(RETORNOS!$I$5:$I$1300,RETORNOS!$I$5:$I$1300),"") -> 0.00011929179
A15: Chequeo diagonal | B15: =IF(ABS(B5-(_xlfn.STDEV.S(RETORNOS!$B$5:$B$1300))^2)<0.0000001,"OK","ERROR") -> OK | C15: La diagonal debe ser la varianza de cada activo

Sheet BETA_CAPM
A1: BETA · CAPM · ALFA
A2: β = Cov(activo, índice) / Var(índice). R² = qué fracción del movimiento explica el índice.
A4: Métrica | B4: XOM | C4: SO | D4: VST | E4: ETN | F4: YPF | G4: WMB | J4: Interpretación
A5: Beta vs XLE | B5: =IFERROR(_xlfn.COVARIANCE.S(RETORNOS!$B$5:$B$1300,RETORNOS!$H$5:$H$1300)/_xlfn.VAR.S(RETORNOS!$H$5:$H$1300),"") -> 0.95778704 | C5: =IFERROR(_xlfn.COVARIANCE.S(RETORNOS!$C$5:$C$1300,RETORNOS!$H$5:$H$1300)/_xlfn.VAR.S(RETORNOS!$H$5:$H$1300),"") -> 0.13235868 | D5: =IFERROR(_xlfn.COVARIANCE.S(RETORNOS!$D$5:$D$1300,RETORNOS!$H$5:$H$1300)/_xlfn.VAR.S(RETORNOS!$H$5:$H$1300),"") -> 0.45469584 | E5: =IFERROR(_xlfn.COVARIANCE.S(RETORNOS!$E$5:$E$1300,RETORNOS!$H$5:$H$1300)/_xlfn.VAR.S(RETORNOS!$H$5:$H$1300),"") -> 0.28648117 | F5: =IFERROR(_xlfn.COVARIANCE.S(RETORNOS!$F$5:$F$1300,RETORNOS!$H$5:$H$1300)/_xlfn.VAR.S(RETORNOS!$H$5:$H$1300),"") -> 0.93316683 | G5: =IFERROR(_xlfn.COVARIANCE.S(RETORNOS!$G$5:$G$1300,RETORNOS!$H$5:$H$1300)/_xlfn.VAR.S(RETORNOS!$H$5:$H$1300),"") -> 0.60307648 | J5: >1 amplifica al sector energía
A6: Beta vs XLU | B6: =IFERROR(_xlfn.COVARIANCE.S(RETORNOS!$B$5:$B$1300,RETORNOS!$I$5:$I$1300)/_xlfn.VAR.S(RETORNOS!$I$5:$I$1300),"") -> 0.3235839 | C6: =IFERROR(_xlfn.COVARIANCE.S(RETORNOS!$C$5:$C$1300,RETORNOS!$I$5:$I$1300)/_xlfn.VAR.S(RETORNOS!$I$5:$I$1300),"") -> 0.88412546 | D6: =IFERROR(_xlfn.COVARIANCE.S(RETORNOS!$D$5:$D$1300,RETORNOS!$I$5:$I$1300)/_xlfn.VAR.S(RETORNOS!$I$5:$I$1300),"") -> 1.1864126 | E6: =IFERROR(_xlfn.COVARIANCE.S(RETORNOS!$E$5:$E$1300,RETORNOS!$I$5:$I$1300)/_xlfn.VAR.S(RETORNOS!$I$5:$I$1300),"") -> 0.53531149 | F6: =IFERROR(_xlfn.COVARIANCE.S(RETORNOS!$F$5:$F$1300,RETORNOS!$I$5:$I$1300)/_xlfn.VAR.S(RETORNOS!$I$5:$I$1300),"") -> 0.50044457 | G6: =IFERROR(_xlfn.COVARIANCE.S(RETORNOS!$G$5:$G$1300,RETORNOS!$I$5:$I$1300)/_xlfn.VAR.S(RETORNOS!$I$5:$I$1300),"") -> 0.61038365 | J6: Alto = se comporta como utility
A7: R² vs XLE | B7: =IFERROR(RSQ(RETORNOS!$B$5:$B$1300,RETORNOS!$H$5:$H$1300),"") -> 0.85271707 | C7: =IFERROR(RSQ(RETORNOS!$C$5:$C$1300,RETORNOS!$H$5:$H$1300),"") -> 0.033107803 | D7: =IFERROR(RSQ(RETORNOS!$D$5:$D$1300,RETORNOS!$H$5:$H$1300),"") -> 0.058764568 | E7: =IFERROR(RSQ(RETORNOS!$E$5:$E$1300,RETORNOS!$H$5:$H$1300),"") -> 0.055249692 | F7: =IFERROR(RSQ(RETORNOS!$F$5:$F$1300,RETORNOS!$H$5:$H$1300),"") -> 0.19437094 | G7: =IFERROR(RSQ(RETORNOS!$G$5:$G$1300,RETORNOS!$H$5:$H$1300),"") -> 0.42208573 | J7: % explicado por energía
A8: R² vs XLU | B8: =IFERROR(RSQ(RETORNOS!$B$5:$B$1300,RETORNOS!$I$5:$I$1300),"") -> 0.044118843 | C8: =IFERROR(RSQ(RETORNOS!$C$5:$C$1300,RETORNOS!$I$5:$I$1300),"") -> 0.66963259 | D8: =IFERROR(RSQ(RETORNOS!$D$5:$D$1300,RETORNOS!$I$5:$I$1300),"") -> 0.1813545 | E8: =IFERROR(RSQ(RETORNOS!$E$5:$E$1300,RETORNOS!$I$5:$I$1300),"") -> 0.08744482 | F8: =IFERROR(RSQ(RETORNOS!$F$5:$F$1300,RETORNOS!$I$5:$I$1300),"") -> 0.025340079 | G8: =IFERROR(RSQ(RETORNOS!$G$5:$G$1300,RETORNOS!$I$5:$I$1300),"") -> 0.19599497 | J8: % explicado por utilities
A9: R² del mejor de los dos | B9: =MAX(B7,B8) -> 0.85271707 | C9: =MAX(C7,C8) -> 0.66963259 | D9: =MAX(D7,D8) -> 0.1813545 | E9: =MAX(E7,E8) -> 0.08744482 | F9: =MAX(F7,F8) -> 0.19437094 | G9: =MAX(G7,G8) -> 0.42208573 | J9: Cuál índice describe mejor al activo
A10: CAPM esperado (vs XLE) | B10: =RESUMEN!$B$7+B5*(RESUMEN!$H$25-RESUMEN!$B$7) -> 0.29742234 | C10: =RESUMEN!$B$7+C5*(RESUMEN!$H$25-RESUMEN!$B$7) -> 0.081175505 | D10: =RESUMEN!$B$7+D5*(RESUMEN!$H$25-RESUMEN!$B$7) -> 0.16562183 | E10: =RESUMEN!$B$7+E5*(RESUMEN!$H$25-RESUMEN!$B$7) -> 0.12155272 | F10: =RESUMEN!$B$7+F5*(RESUMEN!$H$25-RESUMEN!$B$7) -> 0.29097231 | G10: =RESUMEN!$B$7+G5*(RESUMEN!$H$25-RESUMEN!$B$7) -> 0.20449479 | J10: rf + β × prima de mercado
A11: Retorno real (aritmético) | B11: =RESUMEN!H19 -> 0.31458847 | C11: =RESUMEN!H20 -> 0.14216781 | D11: =RESUMEN!H21 -> 0.71103909 | E11: =RESUMEN!H22 -> 0.30943866 | F11: =RESUMEN!H23 -> 0.86819684 | G11: =RESUMEN!H24 -> 0.32807932 | J11: Columna H del RESUMEN
A12: ALFA de Jensen | B12: =B11-B10 -> 0.017166127 | C12: =C11-C10 -> 0.060992305 | D12: =D11-D10 -> 0.54541726 | E12: =E11-E10 -> 0.18788594 | F12: =F11-F10 -> 0.57722453 | G12: =G11-G10 -> 0.12358453 | J12: Lo que sobró tras descontar el riesgo
A13: Riesgo sistemático | B13: =ABS(B5)*RESUMEN!$K$25 -> 0.246651 | C13: =ABS(C5)*RESUMEN!$K$25 -> 0.034085239 | D13: =ABS(D5)*RESUMEN!$K$25 -> 0.11709407 | E13: =ABS(E5)*RESUMEN!$K$25 -> 0.073775133 | F13: =ABS(F5)*RESUMEN!$K$25 -> 0.24031076 | G13: =ABS(G5)*RESUMEN!$K$25 -> 0.15530531 | J13: No diversificable
A14: Riesgo idiosincrático | B14: =IFERROR(SQRT(MAX(0,RESUMEN!K19^2-B13^2)),"") -> 0.10250773 | C14: =IFERROR(SQRT(MAX(0,RESUMEN!K20^2-C13^2)),"") -> 0.18420024 | D14: =IFERROR(SQRT(MAX(0,RESUMEN!K21^2-D13^2)),"") -> 0.46862588 | E14: =IFERROR(SQRT(MAX(0,RESUMEN!K22^2-E13^2)),"") -> 0.30507288 | F14: =IFERROR(SQRT(MAX(0,RESUMEN!K23^2-F13^2)),"") -> 0.48924355 | G14: =IFERROR(SQRT(MAX(0,RESUMEN!K24^2-G13^2)),"") -> 0.18172626 | J14: Sí diversificable
A16: Los benchmarks, para referencia | B16: CAGR | C16: Volatilidad
A17: XLE | B17: =RESUMEN!J25 -> 0.26568155 | C17: =RESUMEN!K25 -> 0.25752175
A18: XLU | B18: =RESUMEN!J26 -> 0.11282456 | C18: =RESUMEN!K26 -> 0.17338262

Sheet OPTIMIZACION
A1: OPTIMIZACIÓN DE PESOS
A2: Verde = las celdas que mueve el Solver.
E3: GRILLA w(i) × w(j) × Cov(i,j) → la varianza es la suma de las 36 celdas
A4: Activo | B4: PESO | C4: Bloque | E4: XOM | F4: SO | G4: VST | H4: ETN | I4: YPF | J4: WMB
A5: XOM | B5: 0.25 | C5: O&G integrada | E5: =IFERROR($B5*B$5*COVARIANZA!B5,0) -> 1.7694581e-05 | F5: =IFERROR($B5*B$6*COVARIANZA!C5,0) -> 2.2121734e-06 | G5: =IFERROR($B5*B$7*COVARIANZA!D5,0) -> 1.7290072e-06 | H5: =IFERROR($B5*B$8*COVARIANZA!E5,0) -> 1.0266404e-06 | I5: =IFERROR($B5*B$9*COVARIANZA!F5,0) -> 5.3737071e-06 | J5: =IFERROR($B5*B$10*COVARIANZA!G5,0) -> 6.5578685e-06 | K5: XOM | L5: GUÍA DEL SOLVER
A6: SO | B6: 0.25 | C6: Utility regulada | E6: =IFERROR($B6*B$5*COVARIANZA!B6,0) -> 2.2121734e-06 | F6: =IFERROR($B6*B$6*COVARIANZA!C6,0) -> 8.7032567e-06 | G6: =IFERROR($B6*B$7*COVARIANZA!D6,0) -> 8.7014871e-07 | H6: =IFERROR($B6*B$8*COVARIANZA!E6,0) -> 1.9510314e-07 | I6: =IFERROR($B6*B$9*COVARIANZA!F6,0) -> 6.4651225e-07 | J6: =IFERROR($B6*B$10*COVARIANZA!G6,0) -> 2.8059061e-06 | K6: SO | L6: Excel: Complementos → Solver
A7: VST | B7: 0.1 | C7: IPP merchant | E7: =IFERROR($B7*B$5*COVARIANZA!B7,0) -> 1.7290072e-06 | F7: =IFERROR($B7*B$6*COVARIANZA!C7,0) -> 8.7014871e-07 | G7: =IFERROR($B7*B$7*COVARIANZA!D7,0) -> 9.2587791e-06 | H7: =IFERROR($B7*B$8*COVARIANZA!E7,0) -> 3.1892125e-06 | I7: =IFERROR($B7*B$9*COVARIANZA!F7,0) -> 2.2252259e-06 | J7: =IFERROR($B7*B$10*COVARIANZA!G7,0) -> 3.380482e-06 | K7: VST | L7: Sheets: Extensiones → Complementos →
A8: ETN | B8: 0.1 | C8: Equipamiento eléctrico | E8: =IFERROR($B8*B$5*COVARIANZA!B8,0) -> 1.0266404e-06 | F8: =IFERROR($B8*B$6*COVARIANZA!C8,0) -> 1.9510314e-07 | G8: =IFERROR($B8*B$7*COVARIANZA!D8,0) -> 3.1892125e-06 | H8: =IFERROR($B8*B$8*COVARIANZA!E8,0) -> 3.9092155e-06 | I8: =IFERROR($B8*B$9*COVARIANZA!F8,0) -> 1.5858013e-06 | J8: =IFERROR($B8*B$10*COVARIANZA!G8,0) -> 1.8726673e-06 | K8: ETN | L8: instalar "Solver" u "OpenSolver"
A9: YPF | B9: 0.1 | C9: Upstream Argentina | E9: =IFERROR($B9*B$5*COVARIANZA!B9,0) -> 5.3737071e-06 | F9: =IFERROR($B9*B$6*COVARIANZA!C9,0) -> 6.4651225e-07 | G9: =IFERROR($B9*B$7*COVARIANZA!D9,0) -> 2.2252259e-06 | H9: =IFERROR($B9*B$8*COVARIANZA!E9,0) -> 1.5858013e-06 | I9: =IFERROR($B9*B$9*COVARIANZA!F9,0) -> 1.179002e-05 | J9: =IFERROR($B9*B$10*COVARIANZA!G9,0) -> 2.9129259e-06 | K9: YPF
A10: WMB | B10: 0.2 | C10: Midstream gas | E10: =IFERROR($B10*B$5*COVARIANZA!B10,0) -> 6.5578685e-06 | F10: =IFERROR($B10*B$6*COVARIANZA!C10,0) -> 2.8059061e-06 | G10: =IFERROR($B10*B$7*COVARIANZA!D10,0) -> 3.380482e-06 | H10: =IFERROR($B10*B$8*COVARIANZA!E10,0) -> 1.8726673e-06 | I10: =IFERROR($B10*B$9*COVARIANZA!F10,0) -> 2.9129259e-06 | J10: =IFERROR($B10*B$10*COVARIANZA!G10,0) -> 9.0705038e-06 | K10: WMB | L10: 1) GMV → minimizá B16
A11: SUMA | B11: =SUM(B5:B10) -> 1 | C11: ← debe dar 100% | L11: 2) Máx Sharpe → maximizá B19
A13: RESULTADOS | L13: Cambiando celdas: $B$5:$B$10
A14: Varianza diaria | B14: =SUM(E5:J10) -> 0.00013359312 | C14: w'Σw | L14: Restricciones:
A15: Volatilidad diaria | B15: =SQRT(B14) -> 0.011558249 | L15: $B$11 = 1
A16: Volatilidad ANUAL | B16: =B15*SQRT(RESUMEN!$B$8) -> 0.18348151 | C16: σ diaria × √252 | L16: $B$5:$B$10 >= RESUMEN!$B$11
A17: Ret. esperado (aritmético) | B17: =((1+SUMPRODUCT($B$5:$B$10,RESUMEN!F19:F24))^RESUMEN!$B$8)*(1+SUMPRODUCT($B$5:$B$10,RESUMEN!D19:D24))-1 -> 0.35207555 | C17: Para optimizar | L17: $B$5:$B$10 <= RESUMEN!$B$12
A18: CAGR REAL | B18: {=IFERROR((INDEX(BACKTEST!$H$5:$H$1300,COUNT(BACKTEST!$H$5:$H$1300))/100)^(RESUMEN!$B$8/COUNT(BACKTEST!$B$5:$B$1300))-1,"")} -> 0.30046416 | C18: Para reportar | L18: $B$9 <= RESUMEN!$B$13 (YPF)
A19: Sharpe (aritmético) | B19: =(B17-RESUMEN!$B$7)/B16 -> 1.6654296
A20: Sharpe (CAGR) | B20: =(B18-RESUMEN!$B$7)/B16 -> 1.3841403 | C20: El publicable | L20: Método: GRG Nonlinear
A21: Beta cartera vs XLE | B21: {=SUMPRODUCT($B$5:$B$10,TRANSPOSE(BETA_CAPM!B5:G5))} -> 0.56058611 | C21: BETA_CAPM está en horizontal → sí lleva TRANSPOSE
A22: Beta cartera vs XLU | B22: {=SUMPRODUCT($B$5:$B$10,TRANSPOSE(BETA_CAPM!B6:G6))} -> 0.64622094 | L22: Corrélo 3 veces desde puntos distintos.
L23: Si no converge al mismo lugar, la matriz
L24: de covarianzas está mal condicionada.

Sheet BACKTEST
A1: BACKTEST — cartera vs XLE vs XLU
A2: Columna E = benchmark 50% XLE + 50% XLU, rebalanceado diariamente (promedio simple de ambos retornos). Optimizar y medir sobre las mismas fechas no es evidencia. Para validar, optimizá con 2/3 de las filas y mirá el tercio final.
A3: Fecha | B3: Ret. cartera | C3: Ret. XLE | D3: Ret. XLU | E3: Ret. 50/50 | F3: Activo vs XLE | G3: Activo vs 50/50 | H3: Cartera base 100 | I3: XLE base 100 | J3: XLU base 100 | K3: 50/50 base 100 | L3: Drawdown cartera
A5: =IF(RETORNOS!A5="","",RETORNOS!A5) -> 44418 | B5: =IF(RETORNOS!B5="","",OPTIMIZACION!$B$5*RETORNOS!B5+OPTIMIZACION!$B$6*RETORNOS!C5+OPTIMIZACION!$B$7*RETORNOS!D5+OPTIMIZACION!$B$8*RETORNOS!E5+OPTIMIZACION!$B$9*RETORNOS!F5+OPTIMIZACION!$B$10*RETORNOS!G5) -> 0.013629023 | C5: =IF(RETORNOS!H5="","",RETORNOS!H5) -> 0.017620675 | D5: =IF(RETORNOS!I5="","",RETORNOS!I5) -> 0.0010614917 | E5: =IF(OR(C5="",D5=""),"",(C5+D5)/2) -> 0.0093410836 | F5: =IF(OR(B5="",C5=""),"",B5-C5) -> -0.0039916522 | G5: =IF(OR(B5="",E5=""),"",B5-E5) -> 0.0042879397 | H5: =IF(B5="","",100*(1+B5)) -> 101.3629 | I5: =IF(C5="","",100*(1+C5)) -> 101.76207 | J5: =IF(D5="","",100*(1+D5)) -> 100.10615 | K5: =IF(E5="","",100*(1+E5)) -> 100.93411 | L5: =IF(H5="","",H5/MAX($H$5:H5)-1) -> 0
A6: =IF(RETORNOS!A6="","",RETORNOS!A6) -> 44419 | B6: =IF(RETORNOS!B6="","",OPTIMIZACION!$B$5*RETORNOS!B6+OPTIMIZACION!$B$6*RETORNOS!C6+OPTIMIZACION!$B$7*RETORNOS!D6+OPTIMIZACION!$B$8*RETORNOS!E6+OPTIMIZACION!$B$9*RETORNOS!F6+OPTIMIZACION!$B$10*RETORNOS!G6) -> 0.0089127353 | C6: =IF(RETORNOS!H6="","",RETORNOS!H6) -> 0.0078429878 | D6: =IF(RETORNOS!I6="","",RETORNOS!I6) -> 0.0093291825 | E6: =IF(OR(C6="",D6=""),"",(C6+D6)/2) -> 0.0085860851 | F6: =IF(OR(B6="",C6=""),"",B6-C6) -> 0.0010697475 | G6: =IF(OR(B6="",E6=""),"",B6-E6) -> 0.00032665018 | H6: =IF(B6="","",H5*(1+B6)) -> 102.26632 | I6: =IF(C6="","",I5*(1+C6)) -> 102.56019 | J6: =IF(D6="","",J5*(1+D6)) -> 101.04006 | K6: =IF(E6="","",K5*(1+E6)) -> 101.80074 | L6: =IF(H6="","",H6/MAX($H$5:H6)-1) -> 0
A7: =IF(RETORNOS!A7="","",RETORNOS!A7) -> 44420 | B7: =IF(RETORNOS!B7="","",OPTIMIZACION!$B$5*RETORNOS!B7+OPTIMIZACION!$B$6*RETORNOS!C7+OPTIMIZACION!$B$7*RETORNOS!D7+OPTIMIZACION!$B$8*RETORNOS!E7+OPTIMIZACION!$B$9*RETORNOS!F7+OPTIMIZACION!$B$10*RETORNOS!G7) -> -0.0004197566 | C7: =IF(RETORNOS!H7="","",RETORNOS!H7) -> -0.000978654 | D7: =IF(RETORNOS!I7="","",RETORNOS!I7) -> 0.0010034244 | E7: =IF(OR(C7="",D7=""),"",(C7+D7)/2) -> 1.2385221e-05 | F7: =IF(OR(B7="",C7=""),"",B7-C7) -> 0.0005588974 | G7: =IF(OR(B7="",E7=""),"",B7-E7) -> -0.00043214182 | H7: =IF(B7="","",H6*(1+B7)) -> 102.2234 | I7: =IF(C7="","",I6*(1+C7)) -> 102.45982 | J7: =IF(D7="","",J6*(1+D7)) -> 101.14144 | K7: =IF(E7="","",K6*(1+E7)) -> 101.802 | L7: =IF(H7="","",H7/MAX($H$5:H7)-1) -> -0.0004197566
A8: =IF(RETORNOS!A8="","",RETORNOS!A8) -> 44421 | B8: =IF(RETORNOS!B8="","",OPTIMIZACION!$B$5*RETORNOS!B8+OPTIMIZACION!$B$6*RETORNOS!C8+OPTIMIZACION!$B$7*RETORNOS!D8+OPTIMIZACION!$B$8*RETORNOS!E8+OPTIMIZACION!$B$9*RETORNOS!F8+OPTIMIZACION!$B$10*RETORNOS!G8) -> -0.0051300743 | C8: =IF(RETORNOS!H8="","",RETORNOS!H8) -> -0.011816874 | D8: =IF(RETORNOS!I8="","",RETORNOS!I8) -> 0.0070640236 | E8: =IF(OR(C8="",D8=""),"",(C8+D8)/2) -> -0.0023764252 | F8: =IF(OR(B8="",C8=""),"",B8-C8) -> 0.0066867996 | G8: =IF(OR(B8="",E8=""),"",B8-E8) -> -0.0027536492 | H8: =IF(B8="","",H7*(1+B8)) -> 101.69898 | I8: =IF(C8="","",I7*(1+C8)) -> 101.24906 | J8: =IF(D8="","",J7*(1+D8)) -> 101.85591 | K8: =IF(E8="","",K7*(1+E8)) -> 101.56007 | L8: =IF(H8="","",H8/MAX($H$5:H8)-1) -> -0.0055476775
A9: =IF(RETORNOS!A9="","",RETORNOS!A9) -> 44424 | B9: =IF(RETORNOS!B9="","",OPTIMIZACION!$B$5*RETORNOS!B9+OPTIMIZACION!$B$6*RETORNOS!C9+OPTIMIZACION!$B$7*RETORNOS!D9+OPTIMIZACION!$B$8*RETORNOS!E9+OPTIMIZACION!$B$9*RETORNOS!F9+OPTIMIZACION!$B$10*RETORNOS!G9) -> -0.0053757718 | C9: =IF(RETORNOS!H9="","",RETORNOS!H9) -> -0.018389836 | D9: =IF(RETORNOS!I9="","",RETORNOS!I9) -> 0.0061025917 | E9: =IF(OR(C9="",D9=""),"",(C9+D9)/2) -> -0.0061436221 | F9: =IF(OR(B9="",C9=""),"",B9-C9) -> 0.013014064 | G9: =IF(OR(B9="",E9=""),"",B9-E9) -> 0.00076785026 | H9: =IF(B9="","",H8*(1+B9)) -> 101.15227 | I9: =IF(C9="","",I8*(1+C9)) -> 99.387107 | J9: =IF(D9="","",J8*(1+D9)) -> 102.47749 | K9: =IF(E9="","",K8*(1+E9)) -> 100.93613 | L9: =IF(H9="","",H9/MAX($H$5:H9)-1) -> -0.010893626
A10: =IF(RETORNOS!A10="","",RETORNOS!A10) -> 44425 | B10: =IF(RETORNOS!B10="","",OPTIMIZACION!$B$5*RETORNOS!B10+OPTIMIZACION!$B$6*RETORNOS!C10+OPTIMIZACION!$B$7*RETORNOS!D10+OPTIMIZACION!$B$8*RETORNOS!E10+OPTIMIZACION!$B$9*RETORNOS!F10+OPTIMIZACION!$B$10*RETORNOS!G10) -> -0.00313115 | C10: =IF(RETORNOS!H10="","",RETORNOS!H10) -> -0.010323412 | D10: =IF(RETORNOS!I10="","",RETORNOS!I10) -> 0.0005776739 | E10: =IF(OR(C10="",D10=""),"",(C10+D10)/2) -> -0.0048728689 | F10: =IF(OR(B10="",C10=""),"",B10-C10) -> 0.0071922616 | G10: =IF(OR(B10="",E10=""),"",B10-E10) -> 0.0017417189 | H10: =IF(B10="","",H9*(1+B10)) -> 100.83555 | I10: =IF(C10="","",I9*(1+C10)) -> 98.361093 | J10: =IF(D10="","",J9*(1+D10)) -> 102.53669 | K10: =IF(E10="","",K9*(1+E10)) -> 100.44428 | L10: =IF(H10="","",H10/MAX($H$5:H10)-1) -> -0.013990667
A11: =IF(RETORNOS!A11="","",RETORNOS!A11) -> 44426 | B11: =IF(RETORNOS!B11="","",OPTIMIZACION!$B$5*RETORNOS!B11+OPTIMIZACION!$B$6*RETORNOS!C11+OPTIMIZACION!$B$7*RETORNOS!D11+OPTIMIZACION!$B$8*RETORNOS!E11+OPTIMIZACION!$B$9*RETORNOS!F11+OPTIMIZACION!$B$10*RETORNOS!G11) -> -0.015117768 | C11: =IF(RETORNOS!H11="","",RETORNOS!H11) -> -0.020812896 | D11: =IF(RETORNOS!I11="","",RETORNOS!I11) -> -0.0050567054 | E11: =IF(OR(C11="",D11=""),"",(C11+D11)/2) -> -0.012934801 | F11: =IF(OR(B11="",C11=""),"",B11-C11) -> 0.0056951275 | G11: =IF(OR(B11="",E11=""),"",B11-E11) -> -0.0021829677 | H11: =IF(B11="","",H10*(1+B11)) -> 99.311141 | I11: =IF(C11="","",I10*(1+C11)) -> 96.313914 | J11: =IF(D11="","",J10*(1+D11)) -> 102.0182 | K11: =IF(E11="","",K10*(1+E11)) -> 99.145051 | L11: =IF(H11="","",H11/MAX($H$5:H11)-1) -> -0.028896927
A12: =IF(RETORNOS!A12="","",RETORNOS!A12) -> 44427 | B12: =IF(RETORNOS!B12="","",OPTIMIZACION!$B$5*RETORNOS!B12+OPTIMIZACION!$B$6*RETORNOS!C12+OPTIMIZACION!$B$7*RETORNOS!D12+OPTIMIZACION!$B$8*RETORNOS!E12+OPTIMIZACION!$B$9*RETORNOS!F12+OPTIMIZACION!$B$10*RETORNOS!G12) -> -0.012683604 | C12: =IF(RETORNOS!H12="","",RETORNOS!H12) -> -0.025957419 | D12: =IF(RETORNOS!I12="","",RETORNOS!I12) -> 0.0040719274 | E12: =IF(OR(C12="",D12=""),"",(C12+D12)/2) -> -0.010942746 | F12: =IF(OR(B12="",C12=""),"",B12-C12) -> 0.013273815 | G12: =IF(OR(B12="",E12=""),"",B12-E12) -> -0.0017408585 | H12: =IF(B12="","",H11*(1+B12)) -> 98.051517 | I12: =IF(C12="","",I11*(1+C12)) -> 93.813853 | J12: =IF(D12="","",J11*(1+D12)) -> 102.43361 | K12: =IF(E12="","",K11*(1+E12)) -> 98.060132 | L12: =IF(H12="","",H12/MAX($H$5:H12)-1) -> -0.041214014
A13: =IF(RETORNOS!A13="","",RETORNOS!A13) -> 44428 | B13: =IF(RETORNOS!B13="","",OPTIMIZACION!$B$5*RETORNOS!B13+OPTIMIZACION!$B$6*RETORNOS!C13+OPTIMIZACION!$B$7*RETORNOS!D13+OPTIMIZACION!$B$8*RETORNOS!E13+OPTIMIZACION!$B$9*RETORNOS!F13+OPTIMIZACION!$B$10*RETORNOS!G13) -> 0.0072203994 | C13: =IF(RETORNOS!H13="","",RETORNOS!H13) -> 0.0021656321 | D13: =IF(RETORNOS!I13="","",RETORNOS!I13) -> 0.01244856 | E13: =IF(OR(C13="",D13=""),"",(C13+D13)/2) -> 0.0073070961 | F13: =IF(OR(B13="",C13=""),"",B13-C13) -> 0.0050547673 | G13: =IF(OR(B13="",E13=""),"",B13-E13) -> -8.6696651e-05 | H13: =IF(B13="","",H12*(1+B13)) -> 98.759488 | I13: =IF(C13="","",I12*(1+C13)) -> 94.017019 | J13: =IF(D13="","",J12*(1+D13)) -> 103.70876 | K13: =IF(E13="","",K12*(1+E13)) -> 98.776667 | L13: =IF(H13="","",H13/MAX($H$5:H13)-1) -> -0.034291197
A14: =IF(RETORNOS!A14="","",RETORNOS!A14) -> 44431 | B14: =IF(RETORNOS!B14="","",OPTIMIZACION!$B$5*RETORNOS!B14+OPTIMIZACION!$B$6*RETORNOS!C14+OPTIMIZACION!$B$7*RETORNOS!D14+OPTIMIZACION!$B$8*RETORNOS!E14+OPTIMIZACION!$B$9*RETORNOS!F14+OPTIMIZACION!$B$10*RETORNOS!G14) -> 0.015619874 | C14: =IF(RETORNOS!H14="","",RETORNOS!H14) -> 0.03746854 | D14: =IF(RETORNOS!I14="","",RETORNOS!I14) -> -0.012863034 | E14: =IF(OR(C14="",D14=""),"",(C14+D14)/2) -> 0.012302753 | F14: =IF(OR(B14="",C14=""),"",B14-C14) -> -0.021848666 | G14: =IF(OR(B14="",E14=""),"",B14-E14) -> 0.0033171212 | H14: =IF(B14="","",H13*(1+B14)) -> 100.3021 | I14: =IF(C14="","",I13*(1+C14)) -> 97.5397 | J14: =IF(D14="","",J13*(1+D14)) -> 102.37475 | K14: =IF(E14="","",K13*(1+E14)) -> 99.991892 | L14: =IF(H14="","",H14/MAX($H$5:H14)-1) -> -0.019206947
A15: =IF(RETORNOS!A15="","",RETORNOS!A15) -> 44432 | B15: =IF(RETORNOS!B15="","",OPTIMIZACION!$B$5*RETORNOS!B15+OPTIMIZACION!$B$6*RETORNOS!C15+OPTIMIZACION!$B$7*RETORNOS!D15+OPTIMIZACION!$B$8*RETORNOS!E15+OPTIMIZACION!$B$9*RETORNOS!F15+OPTIMIZACION!$B$10*RETORNOS!G15) -> 0.0082191919 | C15: =IF(RETORNOS!H15="","",RETORNOS!H15) -> 0.016613558 | D15: =IF(RETORNOS!I15="","",RETORNOS!I15) -> -0.0065203087 | E15: =IF(OR(C15="",D15=""),"",(C15+D15)/2) -> 0.0050466248 | F15: =IF(OR(B15="",C15=""),"",B15-C15) -> -0.0083943664 | G15: =IF(OR(B15="",E15=""),"",B15-E15) -> 0.0031725671 | H15: =IF(B15="","",H14*(1+B15)) -> 101.1265 | I15: =IF(C15="","",I14*(1+C15)) -> 99.160181 | J15: =IF(D15="","",J14*(1+D15)) -> 101.70723 | K15: =IF(E15="","",K14*(1+E15)) -> 100.49651 | L15: =IF(H15="","",H15/MAX($H$5:H15)-1) -> -0.01114562
A16: =IF(RETORNOS!A16="","",RETORNOS!A16) -> 44433 | B16: =IF(RETORNOS!B16="","",OPTIMIZACION!$B$5*RETORNOS!B16+OPTIMIZACION!$B$6*RETORNOS!C16+OPTIMIZACION!$B$7*RETORNOS!D16+OPTIMIZACION!$B$8*RETORNOS!E16+OPTIMIZACION!$B$9*RETORNOS!F16+OPTIMIZACION!$B$10*RETORNOS!G16) -> 0.007348958 | C16: =IF(RETORNOS!H16="","",RETORNOS!H16) -> 0.0076575894 | D16: =IF(RETORNOS!I16="","",RETORNOS!I16) -> 0.0018899861 | E16: =IF(OR(C16="",D16=""),"",(C16+D16)/2) -> 0.0047737877 | F16: =IF(OR(B16="",C16=""),"",B16-C16) -> -0.00030863141 | G16: =IF(OR(B16="",E16=""),"",B16-E16) -> 0.0025751702 | H16: =IF(B16="","",H15*(1+B16)) -> 101.86968 | I16: =IF(C16="","",I15*(1+C16)) -> 99.919509 | J16: =IF(D16="","",J15*(1+D16)) -> 101.89946 | K16: =IF(E16="","",K15*(1+E16)) -> 100.97626 | L16: =IF(H16="","",H16/MAX($H$5:H16)-1) -> -0.003878571
A17: =IF(RETORNOS!A17="","",RETORNOS!A17) -> 44434 | B17: =IF(RETORNOS!B17="","",OPTIMIZACION!$B$5*RETORNOS!B17+OPTIMIZACION!$B$6*RETORNOS!C17+OPTIMIZACION!$B$7*RETORNOS!D17+OPTIMIZACION!$B$8*RETORNOS!E17+OPTIMIZACION!$B$9*RETORNOS!F17+OPTIMIZACION!$B$10*RETORNOS!G17) -> -0.010918844 | C17: =IF(RETORNOS!H17="","",RETORNOS!H17) -> -0.015203645 | D17: =IF(RETORNOS!I17="","",RETORNOS!I17) -> -0.0024673716 | E17: =IF(OR(C17="",D17=""),"",(C17+D17)/2) -> -0.0088355085 | F17: =IF(OR(B17="",C17=""),"",B17-C17) -> 0.0042848017 | G17: =IF(OR(B17="",E17=""),"",B17-E17) -> -0.0020833351 | H17: =IF(B17="","",H16*(1+B17)) -> 100.75738 | I17: =IF(C17="","",I16*(1+C17)) -> 98.400369 | J17: =IF(D17="","",J16*(1+D17)) -> 101.64803 | K17: =IF(E17="","",K16*(1+E17)) -> 100.08409 | L17: =IF(H17="","",H17/MAX($H$5:H17)-1) -> -0.014755065
... A1300: =IF(RETORNOS!A1300="","",RETORNOS!A1300) | B1300: =IF(RETORNOS!B1300="","",OPTIMIZACION!$B$5*RETORNOS!B1300+OPTIMIZACION!$B$6*RETORNOS!C1300+OPTIMIZACION!$B$7*RETORNOS!D1300+OPTIMIZACION!$B$8*RETORNOS!E1300+OPTIMIZACION!$B$9*RETORNOS!F1300+OPTIMIZACION!$B$10*RETORNOS!G1300) | C1300: =IF(RETORNOS!H1300="","",RETORNOS!H1300) | D1300: =IF(RETORNOS!I1300="","",RETORNOS!I1300) | E1300: =IF(OR(C1300="",D1300=""),"",(C1300+D1300)/2) | F1300: =IF(OR(B1300="",C1300=""),"",B1300-C1300) | G1300: =IF(OR(B1300="",E1300=""),"",B1300-E1300) | H1300: =IF(B1300="","",H1299*(1+B1300)) | I1300: =IF(C1300="","",I1299*(1+C1300)) | J1300: =IF(D1300="","",J1299*(1+D1300)) | K1300: =IF(E1300="","",K1299*(1+E1300)) | L1300: =IF(H1300="","",H1300/MAX($H$5:H1300)-1)
